Workbook

Sheet Dashboard
A1: EXCLUSIVE METALS — PRODUCTION DASHBOARD
A2: Live rollup — counts of assemblies currently at each stage. Includes Folded Metal sub-stages. Updates automatically as Detail sheet is edited.
G3: — VENDOR PROCESSING — | K3: — IN-SHOP PIPELINE —
B4: Customer Job | C4: EM Job / Description | D4: Due Date | E4: Days Out | F4: Total Qty | G4: Sent | H4: At Vendor | I4: Ready PU | J4: Parts Proc. | K4: Cut | L4: Fit | M4: Welded | N4: Inspected | O4: Shipped | P4: On Hold | Q4: Status | R4: % Done
B5: S&S 431 | C5: EM 25048 Handrail | E5: =IF(D5="","",IFERROR(D5-TODAY(),DATEVALUE(D5)-TODAY())) | F5: =SUMIFS(Detail!$E$10:$E$209,Detail!$B$10:$B$209,B5) -> 4 | G5: =COUNTIFS(Detail!$B$10:$B$209,B5,Detail!$G$10:$G$209,"Sent to Vendor") -> 0 | H5: =COUNTIFS(Detail!$B$10:$B$209,B5,Detail!$G$10:$G$209,"At Vendor") -> 0 | I5: =COUNTIFS(Detail!$B$10:$B$209,B5,Detail!$G$10:$G$209,"Ready for Pickup") -> 0 | J5: =COUNTIFS(Detail!$B$10:$B$209,B5,Detail!$G$10:$G$209,"Parts Processing") -> 0 | K5: =COUNTIFS(Detail!$B$10:$B$209,B5,Detail!$G$10:$G$209,"Cut") -> 0 | L5: =COUNTIFS(Detail!$B$10:$B$209,B5,Detail!$G$10:$G$209,"Fit") -> 0 | M5: =COUNTIFS(Detail!$B$10:$B$209,B5,Detail!$G$10:$G$209,"Welded") -> 0 | N5: =COUNTIFS(Detail!$B$10:$B$209,B5,Detail!$G$10:$G$209,"Inspected") -> 4 | O5: =COUNTIFS(Detail!$B$10:$B$209,B5,Detail!$G$10:$G$209,"Shipped") -> 0 | P5: =COUNTIFS(Detail!$B$10:$B$209,B5,Detail!$H$10:$H$209,"Yes") -> 0 | Q5: =IF(F5=0,"—",IF(P5>0,"⚠ Hold",IF(O5=F5,"✅ Shipped",IF(N5=F5,"Ready to Ship",IF((I5+H5+G5)>0,"At Vendor",IF((M5+L5+K5)>0,"In Fab","Not Started")))))) -> Ready to Ship | R5: =IF(F5=0,0,(J5*1+G5*2+H5*3+I5*4+K5*5+L5*6+M5*7+N5*8+O5*9)/(9*F5)) -> 0.88888889
B6: S&S 434 | C6: EM 25049 Handrail | E6: =IF(D6="","",IFERROR(D6-TODAY(),DATEVALUE(D6)-TODAY())) | F6: =SUMIFS(Detail!$E$10:$E$209,Detail!$B$10:$B$209,B6) -> 4 | G6: =COUNTIFS(Detail!$B$10:$B$209,B6,Detail!$G$10:$G$209,"Sent to Vendor") -> 0 | H6: =COUNTIFS(Detail!$B$10:$B$209,B6,Detail!$G$10:$G$209,"At Vendor") -> 0 | I6: =COUNTIFS(Detail!$B$10:$B$209,B6,Detail!$G$10:$G$209,"Ready for Pickup") -> 0 | J6: =COUNTIFS(Detail!$B$10:$B$209,B6,Detail!$G$10:$G$209,"Parts Processing") -> 4 | K6: =COUNTIFS(Detail!$B$10:$B$209,B6,Detail!$G$10:$G$209,"Cut") -> 0 | L6: =COUNTIFS(Detail!$B$10:$B$209,B6,Detail!$G$10:$G$209,"Fit") -> 0 | M6: =COUNTIFS(Detail!$B$10:$B$209,B6,Detail!$G$10:$G$209,"Welded") -> 0 | N6: =COUNTIFS(Detail!$B$10:$B$209,B6,Detail!$G$10:$G$209,"Inspected") -> 0 | O6: =COUNTIFS(Detail!$B$10:$B$209,B6,Detail!$G$10:$G$209,"Shipped") -> 0 | P6: =COUNTIFS(Detail!$B$10:$B$209,B6,Detail!$H$10:$H$209,"Yes") -> 0 | Q6: =IF(F6=0,"—",IF(P6>0,"⚠ Hold",IF(O6=F6,"✅ Shipped",IF(N6=F6,"Ready to Ship",IF((I6+H6+G6)>0,"At Vendor",IF((M6+L6+K6)>0,"In Fab","Not Started")))))) -> Not Started | R6: =IF(F6=0,0,(J6*1+G6*2+H6*3+I6*4+K6*5+L6*6+M6*7+N6*8+O6*9)/(9*F6)) -> 0.11111111
B7: S&S 465 | C7: EM 25050 Stairs & Handrail | D7: 09/15/2026 | E7: =IF(D7="","",IFERROR(D7-TODAY(),DATEVALUE(D7)-TODAY())) -> 69 | F7: =SUMIFS(Detail!$E$10:$E$209,Detail!$B$10:$B$209,B7) -> 20 | G7: =COUNTIFS(Detail!$B$10:$B$209,B7,Detail!$G$10:$G$209,"Sent to Vendor") -> 0 | H7: =COUNTIFS(Detail!$B$10:$B$209,B7,Detail!$G$10:$G$209,"At Vendor") -> 0 | I7: =COUNTIFS(Detail!$B$10:$B$209,B7,Detail!$G$10:$G$209,"Ready for Pickup") -> 0 | J7: =COUNTIFS(Detail!$B$10:$B$209,B7,Detail!$G$10:$G$209,"Parts Processing") -> 0 | K7: =COUNTIFS(Detail!$B$10:$B$209,B7,Detail!$G$10:$G$209,"Cut") -> 0 | L7: =COUNTIFS(Detail!$B$10:$B$209,B7,Detail!$G$10:$G$209,"Fit") -> 0 | M7: =COUNTIFS(Detail!$B$10:$B$209,B7,Detail!$G$10:$G$209,"Welded") -> 0 | N7: =COUNTIFS(Detail!$B$10:$B$209,B7,Detail!$G$10:$G$209,"Inspected") -> 17 | O7: =COUNTIFS(Detail!$B$10:$B$209,B7,Detail!$G$10:$G$209,"Shipped") -> 3 | P7: =COUNTIFS(Detail!$B$10:$B$209,B7,Detail!$H$10:$H$209,"Yes") -> 0 | Q7: =IF(F7=0,"—",IF(P7>0,"⚠ Hold",IF(O7=F7,"✅ Shipped",IF(N7=F7,"Ready to Ship",IF((I7+H7+G7)>0,"At Vendor",IF((M7+L7+K7)>0,"In Fab","Not Started")))))) -> Not Started | R7: =IF(F7=0,0,(J7*1+G7*2+H7*3+I7*4+K7*5+L7*6+M7*7+N7*8+O7*9)/(9*F7)) -> 0.90555556
B8: S&S 469 | C8: EM 25051 Stairs & Handrail | D8: 09/30/2026 | E8: =IF(D8="","",IFERROR(D8-TODAY(),DATEVALUE(D8)-TODAY())) -> 84 | F8: =SUMIFS(Detail!$E$10:$E$209,Detail!$B$10:$B$209,B8) -> 19 | G8: =COUNTIFS(Detail!$B$10:$B$209,B8,Detail!$G$10:$G$209,"Sent to Vendor") -> 0 | H8: =COUNTIFS(Detail!$B$10:$B$209,B8,Detail!$G$10:$G$209,"At Vendor") -> 0 | I8: =COUNTIFS(Detail!$B$10:$B$209,B8,Detail!$G$10:$G$209,"Ready for Pickup") -> 0 | J8: =COUNTIFS(Detail!$B$10:$B$209,B8,Detail!$G$10:$G$209,"Parts Processing") -> 19 | K8: =COUNTIFS(Detail!$B$10:$B$209,B8,Detail!$G$10:$G$209,"Cut") -> 0 | L8: =COUNTIFS(Detail!$B$10:$B$209,B8,Detail!$G$10:$G$209,"Fit") -> 0 | M8: =COUNTIFS(Detail!$B$10:$B$209,B8,Detail!$G$10:$G$209,"Welded") -> 0 | N8: =COUNTIFS(Detail!$B$10:$B$209,B8,Detail!$G$10:$G$209,"Inspected") -> 0 | O8: =COUNTIFS(Detail!$B$10:$B$209,B8,Detail!$G$10:$G$209,"Shipped") -> 0 | P8: =COUNTIFS(Detail!$B$10:$B$209,B8,Detail!$H$10:$H$209,"Yes") -> 0 | Q8: =IF(F8=0,"—",IF(P8>0,"⚠ Hold",IF(O8=F8,"✅ Shipped",IF(N8=F8,"Ready to Ship",IF((I8+H8+G8)>0,"At Vendor",IF((M8+L8+K8)>0,"In Fab","Not Started")))))) -> Not Started | R8: =IF(F8=0,0,(J8*1+G8*2+H8*3+I8*4+K8*5+L8*6+M8*7+N8*8+O8*9)/(9*F8)) -> 0.11111111

Sheet Detail
A1: DETAIL — per-assembly entry (shop workstation)
A2: Update Current Stage on each row as work progresses. Dashboard rolls up automatically. One row per shippable assembly.
A3: Stages (in order): | B3: Parts Processing → Sent to Vendor → At Vendor → Ready for Pickup → Cut → Fit → Welded → Inspected → Shipped. In-house parts skip the three vendor stages.
A4: Processing Path: | B4: In-House = all fab done at EM. Folded Metal = larger plate/pipe/HSS sent out for cutting/forming. S&S Steel = larger channels sent out for processing. Vendor parts return for fit/weld/inspection at EM.
A5: Hold: | B5: Set On Hold = Yes and fill in Hold Reason. The assembly keeps its Current Stage; Dashboard shows the held count and the job's Status flips to Hold.
A6: Adding rows: | B6: Type into the next blank row (rows 10-209 are pre-formatted). Dashboard rollup auto-includes new rows in that range.
A9: # | B9: Customer Job | C9: Mark / Assy | D9: Description | E9: Qty | F9: Processing Path | G9: Current Stage | H9: On Hold? | I9: Hold Reason | J9: Crate # | K9: Notes
B10: ▼ S&S 431 — 4 assemblies (click [-] to collapse)
A11: 1 | B11: S&S 431 | C11: 50600HR | D11: Handrail Assembly | E11: 1 | F11: Folded Metal | G11: Inspected | H11: No | K11: Built — awaiting shipment
A12: 2 | B12: S&S 431 | C12: 50601HR | D12: Handrail Assembly | E12: 1 | F12: Folded Metal | G12: Inspected | H12: No | K12: Built — awaiting shipment
A13: 3 | B13: S&S 431 | C13: 50807C | D13: Channel Assembly | E13: 1 | F13: S&S Steel | G13: Inspected | H13: No | K13: Built per Carsen — no material/routing record on file; confirm
A14: 4 | B14: S&S 431 | C14: 50808C | D14: Channel Assembly | E14: 1 | F14: S&S Steel | G14: Inspected | H14: No | K14: Built per Carsen — no material/routing record on file; confirm
B15: ▼ S&S 434 — 4 assemblies (click [-] to collapse)
A16: 5 | B16: S&S 434 | C16: 30600HR | D16: Handrail Assembly | E16: 1 | F16: Folded Metal | G16: Parts Processing | H16: No | K16: Not yet built; material ready to send to Folded Metal
A17: 6 | B17: S&S 434 | C17: 30601HR | D17: Handrail Assembly | E17: 1 | F17: Folded Metal | G17: Parts Processing | H17: No | K17: Not yet built; material ready to send to Folded Metal
A18: 7 | B18: S&S 434 | C18: 30602HR | D18: Handrail Assembly | E18: 1 | F18: Folded Metal | G18: Parts Processing | H18: No | K18: Not yet built; material ready to send to Folded Metal
A19: 8 | B19: S&S 434 | C19: 30603HR | D19: Handrail Assembly | E19: 1 | F19: Folded Metal | G19: Parts Processing | H19: No | K19: Not yet built; material ready to send to Folded Metal
B20: ▼ S&S 465 — 20 assemblies (click [-] to collapse)
A21: 9 | B21: S&S 465 | C21: 500GR | D21: Guardrail Assembly | E21: 1 | F21: Folded Metal | G21: Inspected | H21: No | K21: Built; shipped-vs-staged split pending (BOLs S01/S02 drafted). Path inferred from standard routing (QM-003) — confirm
A22: 10 | B22: S&S 465 | C22: 5000HR | D22: Handrail Assembly | E22: 1 | F22: Folded Metal | G22: Inspected | H22: No | K22: Built; shipped-vs-staged split pending (BOLs S01/S02 drafted). Path inferred from standard routing (QM-003) — confirm
A23: 11 | B23: S&S 465 | C23: 5000S | D23: Stair Assembly | E23: 1 | F23: S&S Steel | G23: Shipped | H23: No | K23: Shipped on S01
A24: 12 | B24: S&S 465 | C24: 5000S-1 | D24: Stair Assembly | E24: 1 | F24: S&S Steel | G24: Shipped | H24: No | K24: Shipped on S01
A25: 13 | B25: S&S 465 | C25: 5000VB | D25: Vertical Brace Assembly | E25: 1 | F25: Folded Metal | G25: Inspected | H25: No | K25: Built; shipped-vs-staged split pending (BOLs S01/S02 drafted). Path inferred from standard routing (QM-003) — confirm
A26: 14 | B26: S&S 465 | C26: 5001GR | D26: Guardrail Assembly | E26: 1 | F26: Folded Metal | G26: Inspected | H26: No | K26: Built; shipped-vs-staged split pending (BOLs S01/S02 drafted). Path inferred from standard routing (QM-003) — confirm
A27: 15 | B27: S&S 465 | C27: 5001HR | D27: Handrail Assembly | E27: 1 | F27: Folded Metal | G27: Inspected | H27: No | K27: Built; shipped-vs-staged split pending (BOLs S01/S02 drafted). Path inferred from standard routing (QM-003) — confirm
A28: 16 | B28: S&S 465 | C28: 5002HR | D28: Handrail Assembly | E28: 1 | F28: Folded Metal | G28: Inspected | H28: No | K28: Built; shipped-vs-staged split pending (BOLs S01/S02 drafted). Path inferred from standard routing (QM-003) — confirm
A29: 17 | B29: S&S 465 | C29: 5002P | D29: Plate Assembly | E29: 1 | F29: Folded Metal | G29: Inspected | H29: No | K29: Built; shipped-vs-staged split pending (BOLs S01/S02 drafted). Path inferred from standard routing (QM-003) — confirm
A30: 18 | B30: S&S 465 | C30: 5003B | D30: Beam Assembly | E30: 1 | F30: Folded Metal | G30: Inspected | H30: No | K30: Built; shipped-vs-staged split pending (BOLs S01/S02 drafted). Path inferred from standard routing (QM-003) — confirm
A31: 19 | B31: S&S 465 | C31: 5003HR | D31: Handrail Assembly | E31: 1 | F31: Folded Metal | G31: Inspected | H31: No | K31: Built; shipped-vs-staged split pending (BOLs S01/S02 drafted). Path inferred from standard routing (QM-003) — confirm
A32: 20 | B32: S&S 465 | C32: 5003P | D32: Plate Assembly | E32: 1 | F32: Folded Metal | G32: Shipped | H32: No | K32: Shipped on S02
... A40: 28 | B40: S&S 465 | C40: 5012P | D40: Plate Assembly | E40: 1 | F40: Folded Metal | G40: Inspected | H40: No | K40: Built; shipped-vs-staged split pending (BOLs S01/S02 drafted). Path inferred from standard routing (QM-003) — confirm
B41: ▼ S&S 469 — 16 assemblies (click [-] to collapse)
A42: 29 | B42: S&S 469 | C42: 8000GR | D42: Guardrail Assembly | E42: 1 | F42: Folded Metal | G42: Parts Processing | H42: No | I42: Awaiting drawing & file revisions before release to Folded Metal | K42: In production — revisions received. Path inferred from standard routing (QM-003) — confirm.
A43: 30 | B43: S&S 469 | C43: 8000HR | D43: Handrail Assembly | E43: 1 | F43: Folded Metal | G43: Parts Processing | H43: No | I43: Awaiting drawing & file revisions before release to Folded Metal | K43: In production — revisions received. Path inferred from standard routing (QM-003) — confirm.
A44: 31 | B44: S&S 469 | C44: 8000L | D44: Ladder Assembly | E44: 1 | F44: Folded Metal | G44: Parts Processing | H44: No | I44: Awaiting drawing & file revisions before release to Folded Metal | K44: In production — revisions received. Path inferred from standard routing (QM-003) — confirm.
A45: 32 | B45: S&S 469 | C45: 8000S | D45: Stair Assembly | E45: 1 | F45: S&S Steel | G45: Parts Processing | H45: No | I45: Awaiting drawing & file revisions before release to Folded Metal | K45: In production — revisions received. Path inferred from standard routing (QM-003) — confirm.
A46: 33 | B46: S&S 469 | C46: 8001GR | D46: Guardrail Assembly | E46: 1 | F46: Folded Metal | G46: Parts Processing | H46: No | I46: Awaiting drawing & file revisions before release to Folded Metal | K46: In production — revisions received. Path inferred from standard routing (QM-003) — confirm.
A47: 34 | B47: S&S 469 | C47: 8001HR | D47: Handrail Assembly | E47: 1 | F47: Folded Metal | G47: Parts Processing | H47: No | I47: Awaiting drawing & file revisions before release to Folded Metal | K47: In production — revisions received. Path inferred from standard routing (QM-003) — confirm.
A48: 35 | B48: S&S 469 | C48: 8001S | D48: Stair Assembly | E48: 1 | F48: S&S Steel | G48: Parts Processing | H48: No | I48: Awaiting drawing & file revisions before release to Folded Metal | K48: In production — revisions received. Path inferred from standard routing (QM-003) — confirm.
A49: 36 | B49: S&S 469 | C49: 8002GR | D49: Guardrail Assembly | E49: 1 | F49: Folded Metal | G49: Parts Processing | H49: No | I49: Awaiting drawing & file revisions before release to Folded Metal | K49: In production — revisions received. Path inferred from standard routing (QM-003) — confirm.
...

Sheet Parts
A1: PARTS — per-stock-type heat traceability (per assembly)
A2: One row per stock type per assembly. Heat # is captured by DCC at receipt (in-house material) or from QC-002-F2 work order (outside processed). Detail tab Heat #(s) column auto-rolls up from this sheet.
A3: Edge case: if same stock type came from MULTIPLE heats for one assembly, split the row — same Assembly Mark + Stock Type, different Piece Marks subsets, different Heat #.
A5: # | B5: Job | C5: Assembly Mark | D5: Stock Type | E5: Piece Marks Included | F5: Qty | G5: Heat # | H5: Notes
A6: S&S 431 — EM 25048 Handrail
A7: 1 | B7: S&S 431 | C7: 50600HR | D7: PI 1-1/2 SCH40 | E7: 50600HR, pi7 (x3), pi8 (x5), pi9 (x4), pi10 (x2) | F7: 15 | G7: 202603447 | H7: Main rail + posts
A8: 2 | B8: S&S 431 | C8: 50600HR | D8: PI 1-1/2 SCH80 | E8: pi1 (x2), pi2 (x3), pi5, pi6 | F8: 7 | G8: 15298321A2 | H8: Heavy-wall pieces
A9: 3 | B9: S&S 431 | C9: 50600HR | D9: L 6x3-1/2x3/8 | E9: a1 (x7) | F9: 7 | G9: HA077453 | H9: Angle clips (recv desc: L 6x4x3/8)
A10: 4 | B10: S&S 431 | C10: 50600HR | D10: PL 1/4" x 4" | E10: pL6, pL7, pL11 | F10: 3 | G10: 15291861A1
A11: 5 | B11: S&S 431 | C11: 50601HR | D11: PI 1-1/2 SCH40 | E11: 50601HR, pi4 (x6) | F11: 7 | G11: 202603447 | H11: Main rail
A12: 6 | B12: S&S 431 | C12: 50601HR | D12: PI 1-1/2 SCH80 | E12: pi1 (x2), pi2 (x2) | F12: 4 | G12: 15298321A2 | H12: Heavy-wall pieces
A13: 7 | B13: S&S 431 | C13: 50601HR | D13: L 6x3-1/2x3/8 | E13: a1 (x4) | F13: 4 | G13: HA077453 | H13: Angle clips
A14: 8 | B14: S&S 431 | C14: 50601HR | D14: PL 1/4" x 4" | E14: pL12 | F14: 1 | G14: 15291861A1
A15: S&S 434 — EM 25049 Handrail (4 rails)
A16: 9 | B16: S&S 434 | C16: 30600HR | D16: FB 1/4" x 4" | E16: pL312 | F16: 1 | G16: 15291861A1
A17: 10 | B17: S&S 434 | C17: 30600HR | D17: PL 1/2" x 5" | E17: pL928 (x3) | F17: 3 | H17: Heat not in receiving log — pre-traceability
A18: 11 | B18: S&S 434 | C18: 30600HR | D18: ROD 1-3/8" | E18: m142 (x3) | F18: 3 | G18: P1375318
A19: 12 | B19: S&S 434 | C19: 30601HR | D19: FB 1/4" x 4" | E19: pL323 | F19: 1 | G19: 15291861A1
A20: 13 | B20: S&S 434 | C20: 30601HR | D20: PL 1/4" x 2-1/2" | E20: pL356 | F20: 1 | G20: 202601934
A21: 14 | B21: S&S 434 | C21: 30601HR | D21: PL 1/2" x 5" | E21: pL928 (x3) | F21: 3 | H21: Heat not in receiving log — pre-traceability
A22: 15 | B22: S&S 434 | C22: 30601HR | D22: ROD 1-3/8" | E22: m142 (x3) | F22: 3 | G22: P1375318
A23: 16 | B23: S&S 434 | C23: 30602HR | D23: FB 1/4" x 4" | E23: pL325, pL926 | F23: 2 | G23: 15291861A1
A24: 17 | B24: S&S 434 | C24: 30602HR | D24: PL 1/4" x 2-1/2" | E24: pL356 | F24: 1 | G24: 202601934
A25: 18 | B25: S&S 434 | C25: 30602HR | D25: PL 1/2" x 5" | E25: pL928 (x4), pL929 | F25: 5 | H25: Heat not in receiving log — pre-traceability
A26: 19 | B26: S&S 434 | C26: 30602HR | D26: ROD 1-3/8" | E26: m142 (x5) | F26: 5 | G26: P1375318
A27: 20 | B27: S&S 434 | C27: 30603HR | D27: FB 1/4" x 4" | E27: pL926, pL927 | F27: 2 | G27: 15291861A1
A28: 21 | B28: S&S 434 | C28: 30603HR | D28: PL 1/4" x 2-1/2" | E28: pL356 | F28: 1 | G28: 202601934
A29: 22 | B29: S&S 434 | C29: 30603HR | D29: PL 1/2" x 5" | E29: pL928 (x4), pL929 | F29: 5 | H29: Heat not in receiving log — pre-traceability
A30: 23 | B30: S&S 434 | C30: 30603HR | D30: ROD 1-3/8" | E30: m142 (x5) | F30: 5 | G30: P1375318
A31: 24 | B31: S&S 434 | D31: PI 1" STD | E31: (job-level — pipe pkg not filed) | F31: 1 | G31: HP004459 | H31: Pipe manifest absent; heat job-level, assembly attribution pending
A32: 25 | B32: S&S 434 | D32: PI 1-1/2" SCH80 | E32: (job-level — pipe pkg not filed) | F32: 3 | G32: 15298321A2 | H32: Assembly attribution pending
A33: 26 | B33: S&S 434 | D33: PI 1-1/2" STD | E33: (job-level — pipe pkg not filed) | F33: 8 | G33: 202603447 | H33: Assembly attribution pending
A34: S&S 465 — EM 25050 Stairs & Handrail
A35: 27 | B35: S&S 465 | D35: C 6x2.157x.437 | F35: 1 | G35: 202603986 | H35: Job-level heat capture from receiving log; per-assembly attribution pending (built before full traceability). Assembly Mark intentionally blank.
A36: 28 | B36: S&S 465 | D36: C 8x2.527x.487 | F36: 2 | G36: 15314241A1
A37: 29 | B37: S&S 465 | D37: C 12x2.96x.300 | F37: 2 | G37: 25679709 (x2) / 14894212A1 (x2) | H37: Multiple heats — cannot split without consumption record
A38: 30 | B38: S&S 465 | D38: FB 1/4" x 2" | F38: 1 | G38: 15266521A1
A39: 31 | B39: S&S 465 | D39: FB 1/4" x 2-1/2" | F39: 1 | G39: 202601934
A40: 32 | B40: S&S 465 | D40: FB 1/4" x 4" | F40: 24 | G40: 15267031A1
A41: 33 | B41: S&S 465 | D41: FB 3/8" x 3-3/4" | F41: 1 | G41: 63435048 | H41: Replaced returned 3/8x1/2 (heat 202605385)
...

Sheet Lookups
A1: JOB COLOR PALETTE | E1: PRODUCTION STAGES (in order)
A2: Color Name | B2: Hex Code | C2: Sample | E2: # | F2: Stage Name | G2: Color | H2: Meaning
A3: Red | B3: D32F2F | E3: 1 | F3: Parts Processing | H3: Work order opened, drawing pulled, material allocated. Decisions made on path (In-House vs Folded Metal). Nothing physical yet.
A4: Blue | B4: 1E63B5 | E4: 2 | F4: Sent to Vendor | H4: Material has been delivered or shipped to the vendor (Folded Metal or S&S Steel) for cutting/forming. Awaiting vendor confirmation of receipt.
A5: Green | B5: 2E8B3D | E5: 3 | F5: At Vendor | H5: The vendor has the parts and is actively processing them. DCC has confirmed work-in-progress with vendor.
A6: Black | B6: 1F1F1F | E6: 4 | F6: Ready for Pickup | H6: The vendor has finished. Parts are at the vendor waiting for EM to pick them up. This is an action-required state — schedule a pickup run.
A7: Yellow | B7: F5C518 | E7: 5 | F7: Cut | H7: Material is in its final cut/formed state IN-HOUSE, ready for fit. Either in-house cut, OR received back from a vendor (Folded Metal/S&S Steel).
E8: 6 | F8: Fit | H8: Parts are fit/assembled prior to weld (mock-up complete).
E9: 7 | F9: Welded | H9: Welding complete. Awaiting QC inspection &#x2014; weld integrity, dim verify, finish check.
E10: 8 | F10: Inspected | H10: QC inspection complete (welds, dims, finish all verified per QC checklist). Ready to be staged for shipment.
E11: 9 | F11: Shipped | H11: Out the door. Reference the shipper number (e.g., S01) in Notes.
E14: PROCESSING PATHS
E15: In-House | H15: All cutting, forming, fitting, and welding done at EM.
E16: Folded Metal | H16: Larger plate / pipe / HSS material sent to Folded Metal for cutting/forming. EM does fit and weld in-house after parts are received back.
E17: S&S Steel | H17: Larger channels sent to S&S Steel for processing. EM does fit and weld in-house after parts are received back.

Sheet Instructions
A1: How to use the Production Tracker (QC-006-F1)
A2: Purpose | B2: A single live view of where every active job is in the production pipeline. Designed to broadcast on the shop TV (Dashboard sheet) and updated from the shop workstation (Detail sheet).
A3: Sheets | B3: Detail sheet = data entry. One row per shippable assembly. Floor updates Current Stage as work progresses. Dashboard sheet = read-only rollup, one row per job. Parts sheet = per-stock-type heat traceability (per assembly); DCC owns this — used when heat # capture is required per customer. Lookups and Instructions are reference.
A4: Workflow | B4: 1) New job kicks off → add a Dashboard row (Job #, Color, Description, Due Date). 2) DCC seeds the Detail sheet with one row per shippable assembly; sets Processing Path = In-House, Folded Metal, or S&S Steel; initial Current Stage = Parts Processing. 3) Shop foreman updates Current Stage at the workstation as each assembly progresses. 4) When an assembly ships, Current Stage → Shipped, add note referencing shipper number (e.g., "On S01").
A5: Stages (all 9, in order) | B5: Parts Processing → Sent to Vendor → At Vendor → Ready for Pickup → Cut → Fit → Welded → Inspected → Shipped. Stages 2-4 apply only to assemblies routed through a vendor (Folded Metal or S&S Steel). In-house parts skip them and go from Parts Processing directly to Cut.
A6: Vendor processing lifecycle | B6: Sent to Vendor: material physically left EM, awaiting vendor confirmation of receipt. At Vendor: vendor has confirmed they're working on the parts. Ready for Pickup: vendor finished — schedule a pickup. Once picked up and back at EM, advance to Cut (the parts are now in cut form in-house, ready for fit).
A7: Partial FM batches | B7: If Folded Metal returns only some components of an assembly (e.g., 3 of 5 plates back, 2 still at FM), keep Current Stage at the worst remaining state — typically 'At Vendor' or 'Ready for Pickup'. Use the Notes column to track the breakdown: '3 of 5 received [date]. Awaiting 2 from FM.' Only advance Current Stage to Cut once ALL components are physically back at EM. Rule of thumb: assembly's stage = the earliest stage any of its components is at.
A8: Hold | B8: Set On Hold = Yes and fill in Hold Reason. The assembly keeps its Current Stage; Dashboard shows held count and job's Status flips to Hold. Hold reasons should be specific: "Awaiting drawing rev confirmation" not "Stuck."
A9: Parts tab | B9: One row per stock type per assembly. Captures which heat # was used for which piece marks. Owned by Document Control. Not currently active for shop floor — DCC will populate as heat capture becomes required (e.g., customer spec, code work). Job header rows are colored to match the Dashboard palette and data rows collapse under each job header (click the [-] outline button at the top-left). Edge case: if a single stock type came from multiple heats for the same assembly, split the row — same Assembly Mark + Stock Type, different Piece Marks subsets, different Heat #.
A10: Crate # | B10: When the crate builder loads an assembly into a shipping crate, they write the crate number on the Detail row. Format: 'C-01', 'C-02' for crates within a single shipment, or shipper-prefixed (e.g., 'S03-C01'). This links each assembly to its physical shipping container so the shipper docx (QC-006-F2) can be filled out from this data.
A11: Color coding | B11: Each job gets a single color from the palette in Lookups. The same color is used to physically mark material on the floor (paint pen, tag, etc.) so shop personnel can match material to a job at a glance. Dashboard shows the color band on the left of each job's row.
A12: Dashboard logic | B12: Each stage column shows the COUNT OF ASSEMBLIES CURRENTLY AT THAT EXACT STAGE for the job. So you can see distribution at a glance: e.g., '0 Parts Proc, 1 Sent, 2 At Vendor, 1 Ready PU, 1 Cut, 0 Fit, 3 Welded, 2 Inspected, 2 Shipped' tells you exactly where each piece is.
A13: Status column | B13: Derived from rollup. Hold beats everything. Then Shipped (all shipped), Ready to Ship (all inspected), At Vendor (anything at a vendor stage), In Fab (any in-shop work after Parts Processing), otherwise Not Started.
... A18: Retention | B18: Per QC-006 §15, retained 7 years from job close. At job close, archive workbook to 02_Closed Jobs/[Year]/[Job#]/.
